Workbook

Sheet Fee Breakdown by Entity
A1: Amicorp Self-Service Portal — Complete Entity Fee & Product Information
A2: Indicative fees only — subject to local office confirmation, client profile, complexity, and applicable taxes. Rows marked † have no line-item fee schedule; Setup and Annual totals shown. Filing Required = Yes where income tax or annual financial statements/regulatory return is required. Hourly rates: USD 100–750/hr where not otherwise specified.
A3: Entity Information | F3: Product Content | V3: Enrichment — Structure & Regulation | AD3: Setup Fee (One-off) | AP3: Annual Resposibility Fees (Recurring) | BD3: Reporting & Compliance (As Required) | BR3: Set-up Fee (on-off) | BT3: Set-up Fee (on-off) | BV3: Set-up Fee (on-off) | BX3: Set-up Fee (on-off) | BZ3: Set-up Fee (on-off) | CP3: FATCA / CRS / ESR / MDR Items | DB3: Hourly Rates
A4: Country | B4: LMT Member | C4: Service Type | D4: Entity / Product | E4: Currency | F4: Description | G4: Overview | H4: Setup Time | I4: Ongoing Compliance | J4: Benefit 1 | K4: Benefit 2 | L4: Benefit 3 | M4: Benefit 4 | N4: Ideal for 1 | O4: Ideal for 2 | P4: Ideal for 3 | Q4: Ideal for 4 | R4: Key Feature 1 | S4: Key Feature 2 | T4: Key Feature 3 | U4: Key Feature 4 | V4: Entity Type Category | W4: Legal Framework | X4: Liability Protection | Y4: Regulatory Body / Key Statute | Z4: Public Register | AA4: Min Shareholders | AB4: Typical Use Case | AC4: Risk / Restriction | AD4: Setup Fee | AE4: M/O | AF4: Incorporation Third Party Expenses | AG4: M/O | AH4: Tax identification code | AI4: M/O | AJ4: UBO classification and registry | AK4: M/O | AL4: Bank Account Opening with Amicorp Bank & Trust | AM4: M/O | AN4: Bank Account Opening Third Party Bank (retainer) | AO4: M/O | AP4: Corporate Director Fee | AQ4: M/O | AR4: Trustee Fee | AS4: M/O | AT4: Personal Director Fee | AU4: M/O | AV4: Registered Office Fee | AW4: M/O | AX4: Corporate Secretary Fee | AY4: M/O | AZ4: Government Fee | BA4: M/O | BB4: Regulatory Authority Fee | BC4: M/O | BD4: Accounting (Retainer) | BE4: M/O | BF4: Tax Filing (Retainer) | BG4: M/O | BH4: Annual General Meeting / Board Minutes | BI4: M/O | BJ4: Audit (External Auditors) | BK4: M/O | BL4: Compliance Fee | BM4: M/O | BN4: Economic Substance Filing | BO4: M/O | BP4: UBO Registry Filing | BQ4: M/O | BR4: Fund Formation (Retainer) | BS4: M/O | BT4: Fund Compartment Formation | BU4: M/O | BV4: Preparation of Private Placement Memorandum | BW4: M/O | BX4: Regulatory fees | BY4: M/O | BZ4: Fund Management Services | CA4: M/O | CB4: Fund Administration & NAV calculation | CC4: M/O | CD4: Registrar and transfer agent | CE4: M/O | CF4: Investor KYC and subscription | CG4: M/O | CH4: Fund Director | CI4: M/O | CJ4: Money Laundering Reporting Officer (Retainer) | CK4: M/O | CL4: Annual audit coordination (Retainer) | CM4: M/O | CN4: Financial Statements (Retainer) | CO4: M/O | CP4: FATCA/CRS classification (one-off) | CQ4: M/O | CR4: ESR classification (one-off): | CS4: M/O | CT4: ESR Annual Declaration: USD 125 (fees may vary subject to ESR classification) | CU4: M/O | CV4: ESR Annual Notification: USD 165 | CW4: M/O | CX4: Legal and Corporate work (Retainer) | CY4: M/O | CZ4: Accounting and tax filing (Retainer) | DA4: M/O | DB4: Hourly Rates (Legal & Accounting) | DC4: M/O | DD4: Disbursements (7.5%) | DE4: 3rd Sheet | DF4: 1stSheet | DG4: Check
A5: BAHAMAS | DE5: ##
A6: Bahamas | B6: Marvin Taylor | C6: Company | D6: Bahamas IBC | E6: USD | F6: International Business Company offering tax-neutral structure for international trade and investment holding. | G6: The Bahamas IBC is a entity structure regulated under local law and widely used by international clients of Amicorp. International Business Company offering tax-neutral structure for international trade and investment holding. Our local team manages incorporation, ongoing administration, accounting, and compliance so you can focus on commercial objectives instead of paperwork. | H6: 3-7 business days | I6: Annual return, financial statements filing, and economic substance / UBO declarations | J6: Established Bahamas legal framework familiar to investors, banks, and counterparties | K6: End-to-end Amicorp service: incorporation, registered office, directors, accounting, and reporting | L6: Treaty network and regulatory standing supporting cross-border investment and capital flows | M6: Single point of contact across 30+ jurisdictions for multi-entity group structures | N6: Holding investments into and out of Bahamas | O6: Group holding companies and intermediate SPVs | P6: Joint ventures and shareholder agreements | Q6: Operating subsidiaries with local market access | R6: Limited liability for shareholders | S6: Separate legal entity | T6: Flexible management structure | U6: Tax efficient | V6: IBC | W6: Common Law | X6: Full | Y6: Bahamas Registrar General International Business Companies Act 2000 | Z6: No | AA6: 1 | AB6: Cross-border holding of securities, IP, or real estate outside the Bahamas | AC6: Cannot trade within Bahamas; economic substance rules apply for certain activities | AD6: 1560 | AE6: M | AG6: O | AI6: N/A | AK6: N/A | AL6: 0 | AM6: M | AO6: N/A | AP6: 1560 | AQ6: O | AS6: N/A | AT6: — | AU6: O | AV6: 860 | AW6: M | AX6: 590 | AY6: M | AZ6: 350 | BA6: M | BC6: M | BD6: — | BE6: M | BF6: — | BG6: M | BI6: N/A | BK6: N/A | BM6: N/A | BO6: N/A | BQ6: N/A | BS6: N/A | BU6: N/A | BW6: N/A | BY6: N/A | CA6: N/A | CC6: N/A | CE6: N/A | CG6: N/A | CK6: N/A | CM6: N/A | CO6: N/A | CP6: 400 | CQ6: M | CR6: 300 | CS6: M | CT6: 125 | CU6: M | CW6: N/A | CY6: N/A | DA6: N/A | DB6: USD 100–750/hr (confirm with local office) | DC6: O | DD6: =ROUND(0.075*SUM(AD6,AF6,AH6,AJ6,AL6,AN6,AP6,AR6,AT6,AV6,AX6,AZ6,BB6,BR6,BT6,BV6,BX6,BZ6,CB6,CD6,CF6,CJ6,CL6,CN6,CP6,CR6,CT6,CV6,CX6,CZ6),0) -> 431 | DE6: Bahamas#Company#Bahamas IBC | DF6: =A6&"#"&C6&"#"&D6 -> Bahamas#Company#Bahamas IBC | DG6: =DE6=DF6 -> TRUE
A7: Bahamas | B7: Marvin Taylor | C7: Trust | D7: Bahamas Trust | E7: USD | F7: Discretionary or fixed trust structure for asset protection and succession planning. | G7: The Bahamas Trust is a trust structure regulated under local law and widely used by international clients of Amicorp. Discretionary or fixed trust structure for asset protection and succession planning. Our local team manages incorporation, ongoing administration, accounting, and compliance so you can focus on commercial objectives instead of paperwork. | H7: 5-10 business days | I7: Annual trustee review, beneficiary statements, FATCA/CRS reporting where applicable | J7: Established Bahamas legal framework familiar to investors, banks, and counterparties | K7: End-to-end Amicorp service: incorporation, registered office, directors, accounting, and reporting | L7: Treaty network and regulatory standing supporting cross-border investment and capital flows | M7: Single point of contact across 30+ jurisdictions for multi-entity group structures | N7: High-net-worth families consolidating assets across jurisdictions | O7: Succession and inheritance planning for global families | P7: Asset protection from political, creditor, or matrimonial risks | Q7: Holding shares of a private trust company or family business | R7: Asset protection from third-party claims | S7: Multi-generational succession planning | T7: Confidentiality and privacy of beneficial ownership | U7: Flexible distribution control by trustee | V7: Trust | W7: Common Law | X7: Full (trustee liability only) | Y7: Bahamas Financial Intelligence Unit / Central Bank Trustee Act 1998; Purpose Trust Act 2004 | Z7: No | AB7: Multi-generational wealth preservation with discretionary distributions for HNW families | AC7: CRS/FATCA reporting obligations; trustee must be licensed | AD7: 4500 | AE7: M | AG7: O | AI7: N/A | AK7: N/A | AL7: 0 | AM7: M | AO7: N/A | AQ7: N/A | AR7: 3500 | AS7: M | AT7: — | AU7: O | AV7: — | AW7: M | AX7: — | AY7: M | AZ7: — | BA7: M | BC7: M | BD7: — | BE7: M | BF7: — | BG7: M | BI7: N/A | BK7: N/A | BM7: N/A | BO7: N/A | BQ7: N/A | BS7: N/A | BU7: N/A | BW7: N/A | BY7: N/A | CA7: N/A | CC7: N/A | CE7: N/A | CG7: N/A | CK7: N/A | CM7: N/A | CO7: N/A | CP7: 400 | CQ7: M | CR7: 300 | CS7: M | CT7: 125 | CU7: M | CW7: N/A | CY7: N/A | DA7: N/A | DB7: USD 100–750/hr (confirm with local office) | DC7: O | DD7: =ROUND(0.075*SUM(AD7,AF7,AH7,AJ7,AL7,AN7,AP7,AR7,AT7,AV7,AX7,AZ7,BB7,BR7,BT7,BV7,BX7,BZ7,CB7,CD7,CF7,CJ7,CL7,CN7,CP7,CR7,CT7,CV7,CX7,CZ7),0) -> 662 | DE7: Bahamas#Trust#Bahamas Trust | DF7: =A7&"#"&C7&"#"&D7 -> Bahamas#Trust#Bahamas Trust | DG7: =DE7=DF7 -> TRUE
A8: Bahamas | B8: Marvin Taylor | C8: Fund | D8: Bahamas Ltd | E8: USD | F8: Private Limited Company offering limited liability with straightforward corporate governance. | G8: The Bahamas Ltd is a fund structure regulated under local law and widely used by international clients of Amicorp. Private Limited Company offering limited liability with straightforward corporate governance. Our local team manages incorporation, ongoing administration, accounting, and compliance so you can focus on commercial objectives instead of paperwork. | H8: 4-6 weeks | I8: Annual audited financials, regulator filings, AML/KYC monitoring, and investor reporting | J8: Established Bahamas legal framework familiar to investors, banks, and counterparties | K8: End-to-end Amicorp service: incorporation, registered office, directors, accounting, and reporting | L8: Treaty network and regulatory standing supporting cross-border investment and capital flows | M8: Single point of contact across 30+ jurisdictions for multi-entity group structures | N8: Asset managers launching regulated or private funds | O8: PE/VC sponsors raising committed capital from institutional LPs | P8: Family offices pooling investments across asset classes | Q8: Structured products and securitisation arrangers | R8: Pooled capital with professional management | S8: Investor-friendly structure with familiar legal precedent | T8: Tax-efficient flow-through or treaty-eligible vehicle | U8: Scalable for additional sub-funds or share classes | V8: Investment Fund (Private) | W8: Common Law | X8: Full | Y8: Securities Commission of the Bahamas Investment Funds Act 2019 | Z8: No | AA8: 1 | AB8: Private closed-end investment vehicle for accredited investors | AC8: Must appoint licensed fund administrator; annual audit required | AE8: M | AG8: O | AI8: N/A | AK8: N/A | AL8: 0 | AM8: M | AO8: N/A | AP8: — | AQ8: M | AS8: N/A | AT8: — | AU8: O | AV8: — | AW8: M | AX8: — | AY8: M | AZ8: — | BA8: M | BC8: M | BD8: — | BE8: M | BF8: — | BG8: M | BI8: N/A | BK8: N/A | BM8: N/A | BO8: N/A | BQ8: N/A | BR8: 12000 | BS8: M | BU8: N/A | BW8: N/A | BY8: N/A | CA8: N/A | CB8: 2-8 Basispoints (2,000 USD per month minimum fee) | CC8: O | CE8: N/A | CG8: N/A | CH8: 5000 | CI8: O | CJ8: 2500 | CK8: O | CL8: 1500 | CM8: O | CN8: 1500 | CO8: O | CP8: 400 | CQ8: M | CR8: 300 | CS8: M | CT8: 125 | CU8: M | CW8: N/A | CY8: N/A | DA8: N/A | DB8: USD 100–750/hr (confirm with local office) | DC8: O | DD8: =ROUND(0.075*SUM(AD8,AF8,AH8,AJ8,AL8,AN8,AP8,AR8,AT8,AV8,AX8,AZ8,BB8,BR8,BT8,BV8,BX8,BZ8,CB8,CD8,CF8,CJ8,CL8,CN8,CP8,CR8,CT8,CV8,CX8,CZ8),0) -> 1374 | DE8: Bahamas#Fund#Bahamas Ltd | DF8: =A8&"#"&C8&"#"&D8 -> Bahamas#Fund#Bahamas Ltd | DG8: =DE8=DF8 -> TRUE
A9: Bahamas | B9: Marvin Taylor | C9: Fund | D9: Bahamas Exempt LP | E9: USD | F9: Exempted Limited Partnership, the most popular vehicle for PE/VC/RE funds. | G9: The Bahamas Exempt LP is a fund structure regulated under local law and widely used by international clients of Amicorp. Exempted Limited Partnership, the most popular vehicle for PE/VC/RE funds. Our local team manages incorporation, ongoing administration, accounting, and compliance so you can focus on commercial objectives instead of paperwork. | H9: 4-6 weeks | I9: Annual audited financials, regulator filings, AML/KYC monitoring, and investor reporting | J9: Established Bahamas legal framework familiar to investors, banks, and counterparties | K9: End-to-end Amicorp service: incorporation, registered office, directors, accounting, and reporting | L9: Treaty network and regulatory standing supporting cross-border investment and capital flows | M9: Single point of contact across 30+ jurisdictions for multi-entity group structures | N9: Asset managers launching regulated or private funds | O9: PE/VC sponsors raising committed capital from institutional LPs | P9: Family offices pooling investments across asset classes | Q9: Structured products and securitisation arrangers | R9: Pooled capital with professional management | S9: Investor-friendly structure with familiar legal precedent | T9: Tax-efficient flow-through or treaty-eligible vehicle | U9: Scalable for additional sub-funds or share classes | V9: Investment Fund (Private) | W9: Common Law | X9: Full for LPs; unlimited for GP | Y9: Securities Commission of the Bahamas Exempted Limited Partnership Act 1995 | Z9: No | AA9: 1 GP + 1 LP | AB9: PE and VC fund structures with US-style LP economics and carry arrangements | AC9: GP has unlimited liability unless a corporate GP is used | AE9: M | AG9: O | AI9: N/A | AK9: N/A | AL9: 0 | AM9: M | AO9: N/A | AP9: — | AQ9: M | AS9: N/A | AT9: — | AU9: O | AV9: — | AW9: M | AX9: — | AY9: M | AZ9: — | BA9: M | BC9: M | BD9: — | BE9: M | BF9: — | BG9: M | BI9: N/A | BK9: N/A | BM9: N/A | BO9: N/A | BQ9: N/A | BR9: 12000 | BS9: M | BU9: N/A | BW9: N/A | BY9: N/A | CA9: N/A | CB9: 2-8 Basispoints (2,000 USD per month minimum fee) | CC9: O | CE9: N/A | CG9: N/A | CH9: 5000 | CI9: O | CJ9: 2500 | CK9: O | CL9: 1500 | CM9: O | CN9: 1500 | CO9: O | CP9: 400 | CQ9: M | CR9: 300 | CS9: M | CT9: 125 | CU9: M | CW9: N/A | CY9: N/A | DA9: N/A | DB9: USD 100–750/hr (confirm with local office) | DC9: O | DD9: =ROUND(0.075*SUM(AD9,AF9,AH9,AJ9,AL9,AN9,AP9,AR9,AT9,AV9,AX9,AZ9,BB9,BR9,BT9,BV9,BX9,BZ9,CB9,CD9,CF9,CJ9,CL9,CN9,CP9,CR9,CT9,CV9,CX9,CZ9),0) -> 1374 | DE9: Bahamas#Fund#Bahamas Exempt LP | DF9: =A9&"#"&C9&"#"&D9 -> Bahamas#Fund#Bahamas Exempt LP | DG9: =DE9=DF9 -> TRUE
A10: Bahamas | B10: Marvin Taylor | C10: Fund | D10: Bahamas Unit Trust | E10: USD | F10: Pooled investment vehicle where investors hold units representing beneficial interest. | G10: The Bahamas Unit Trust is a fund structure regulated under local law and widely used by international clients of Amicorp. Pooled investment vehicle where investors hold units representing beneficial interest. Our local team manages incorporation, ongoing administration, accounting, and compliance so you can focus on commercial objectives instead of paperwork. | H10: 4-6 weeks | I10: Annual audited financials, regulator filings, AML/KYC monitoring, and investor reporting | J10: Established Bahamas legal framework familiar to investors, banks, and counterparties | K10: End-to-end Amicorp service: incorporation, registered office, directors, accounting, and reporting | L10: Treaty network and regulatory standing supporting cross-border investment and capital flows | M10: Single point of contact across 30+ jurisdictions for multi-entity group structures | N10: Asset managers launching regulated or private funds | O10: PE/VC sponsors raising committed capital from institutional LPs | P10: Family offices pooling investments across asset classes | Q10: Structured products and securitisation arrangers | R10: Pooled capital with professional management | S10: Investor-friendly structure with familiar legal precedent | T10: Tax-efficient flow-through or treaty-eligible vehicle | U10: Scalable for additional sub-funds or share classes | V10: Investment Fund (Private) | W10: Common Law | X10: Full (trustee liability only) | Y10: Securities Commission of the Bahamas Investment Funds Act 2019 | Z10: No | AA10: 1 trustee + 1 unitholder | AB10: Pooled investment structures for retail or institutional investors in listed or unlisted assets | AC10: Trustee must be licensed; subject to Investment Funds Act licensing | AE10: M | AG10: O | AI10: N/A | AK10: N/A | AL10: 0 | AM10: M | AO10: N/A | AP10: — | AQ10: M | AS10: N/A | AT10: — | AU10: O | AV10: — | AW10: M | AX10: — | AY10: M | AZ10: — | BA10: M | BC10: M | BD10: — | BE10: M | BF10: — | BG10: M | BI10: N/A | BK10: N/A | BM10: N/A | BO10: N/A | BQ10: N/A | BR10: 12000 | BS10: M | BU10: N/A | BW10: N/A | BY10: N/A | CA10: N/A | CB10: 2-8 Basispoints (2,000 USD per month minimum fee) | CC10: O | CE10: N/A | CG10: N/A | CH10: 5000 | CI10: O | CJ10: 2500 | CK10: O | CL10: 1500 | CM10: O | CN10: 1500 | CO10: O | CP10: 400 | CQ10: M | CR10: 300 | CS10: M | CT10: 125 | CU10: M | CW10: N/A | CY10: N/A | DA10: N/A | DB10: USD 100–750/hr (confirm with local office) | DC10: O | DD10: =ROUND(0.075*SUM(AD10,AF10,AH10,AJ10,AL10,AN10,AP10,AR10,AT10,AV10,AX10,AZ10,BB10,BR10,BT10,BV10,BX10,BZ10,CB10,CD10,CF10,CJ10,CL10,CN10,CP10,CR10,CT10,CV10,CX10,CZ10),0) -> 1374 | DE10: Bahamas#Fund#Bahamas Unit Trust | DF10: =A10&"#"&C10&"#"&D10 -> Bahamas#Fund#Bahamas Unit Trust | DG10: =DE10=DF10 -> TRUE
A11: Bahamas | B11: Marvin Taylor | C11: Fund | D11: Bahamas SAC | E11: USD | F11: Segregated Accounts Company allowing ring-fenced investment portfolios. | G11: The Bahamas SAC is a fund structure regulated under local law and widely used by international clients of Amicorp. Segregated Accounts Company allowing ring-fenced investment portfolios. Our local team manages incorporation, ongoing administration, accounting, and compliance so you can focus on commercial objectives instead of paperwork. | H11: 4-6 weeks | I11: Annual audited financials, regulator filings, AML/KYC monitoring, and investor reporting | J11: Established Bahamas legal framework familiar to investors, banks, and counterparties | K11: End-to-end Amicorp service: incorporation, registered office, directors, accounting, and reporting | L11: Treaty network and regulatory standing supporting cross-border investment and capital flows | M11: Single point of contact across 30+ jurisdictions for multi-entity group structures | N11: Asset managers launching regulated or private funds | O11: PE/VC sponsors raising committed capital from institutional LPs | P11: Family offices pooling investments across asset classes | Q11: Structured products and securitisation arrangers | R11: Pooled capital with professional management | S11: Investor-friendly structure with familiar legal precedent | T11: Tax-efficient flow-through or treaty-eligible vehicle | U11: Scalable for additional sub-funds or share classes | V11: Segregated Portfolio Company | W11: Common Law | X11: Full (statutory cell segregation) | Y11: Securities Commission of the Bahamas Segregated Accounts Companies Act 2004 | Z11: No | AA11: 1 | AB11: Multi-class investment fund with legally ring-fenced portfolios in a single entity | AC11: Cell segregation not always recognised in foreign jurisdictions; legal opinion required | AE11: M | AG11: O | AI11: N/A | AK11: N/A | AL11: 0 | AM11: M | AO11: N/A | AP11: — | AQ11: M | AS11: N/A | AT11: — | AU11: O | AV11: — | AW11: M | AX11: — | AY11: M | AZ11: — | BA11: M | BC11: M | BD11: — | BE11: M | BF11: — | BG11: M | BI11: N/A | BK11: N/A | BM11: N/A | BO11: N/A | BQ11: N/A | BR11: 12000 | BS11: M | BU11: N/A | BW11: N/A | BY11: N/A | CA11: N/A | CB11: 2-8 Basispoints (2,000 USD per month minimum fee) | CC11: O | CE11: N/A | CG11: N/A | CH11: 5000 | CI11: O | CJ11: 2500 | CK11: O | CL11: 1500 | CM11: O | CN11: 1500 | CO11: O | CP11: 400 | CQ11: M | CR11: 300 | CS11: M | CT11: 125 | CU11: M | CW11: N/A | CY11: N/A | DA11: N/A | DB11: USD 100–750/hr (confirm with local office) | DC11: O | DD11: =ROUND(0.075*SUM(AD11,AF11,AH11,AJ11,AL11,AN11,AP11,AR11,AT11,AV11,AX11,AZ11,BB11,BR11,BT11,BV11,BX11,BZ11,CB11,CD11,CF11,CJ11,CL11,CN11,CP11,CR11,CT11,CV11,CX11,CZ11),0) -> 1374 | DE11: Bahamas#Fund#Bahamas SAC | DF11: =A11&"#"&C11&"#"&D11 -> Bahamas#Fund#Bahamas SAC | DG11: =DE11=DF11 -> TRUE
A12: Bahamas | B12: Marvin Taylor | C12: Fund | D12: Bahamas ICON | E12: USD | F12: Bahamian Investment Condominium — innovative co-ownership fund structure. | G12: The Bahamas ICON is a fund structure regulated under local law and widely used by international clients of Amicorp. Bahamian Investment Condominium — innovative co-ownership fund structure. Our local team manages incorporation, ongoing administration, accounting, and compliance so you can focus on commercial objectives instead of paperwork. | H12: 4-6 weeks | I12: Annual audited financials, regulator filings, AML/KYC monitoring, and investor reporting | J12: Established Bahamas legal framework familiar to investors, banks, and counterparties | K12: End-to-end Amicorp service: incorporation, registered office, directors, accounting, and reporting | L12: Treaty network and regulatory standing supporting cross-border investment and capital flows | M12: Single point of contact across 30+ jurisdictions for multi-entity group structures | N12: Asset managers launching regulated or private funds | O12: PE/VC sponsors raising committed capital from institutional LPs | P12: Family offices pooling investments across asset classes | Q12: Structured products and securitisation arrangers | R12: Pooled capital with professional management | S12: Investor-friendly structure with familiar legal precedent | T12: Tax-efficient flow-through or treaty-eligible vehicle | U12: Scalable for additional sub-funds or share classes | V12: Investment Fund (Private) | W12: Common Law | X12: Full (proportionate to co-ownership interest) | Y12: Securities Commission of the Bahamas Investment Condominium Act 2003 | Z12: No | AA12: 2+ | AB12: Real asset co-ownership structures (real estate, infrastructure) without corporate form | AC12: Niche structure; limited precedent; may not be recognised in all jurisdictions | AE12: M | AG12: O | AI12: N/A | AK12: N/A | AL12: 0 | AM12: M | AO12: N/A | AP12: — | AQ12: M | AS12: N/A | AT12: — | AU12: O | AV12: — | AW12: M | AX12: — | AY12: M | AZ12: — | BA12: M | BC12: M | BD12: — | BE12: M | BF12: — | BG12: M | BI12: N/A | BK12: N/A | BM12: N/A | BO12: N/A | BQ12: N/A | BR12: 12000 | BS12: M | BU12: N/A | BW12: N/A | BY12: N/A | CA12: N/A | CB12: 2-8 Basispoints (2,000 USD per month minimum fee) | CC12: O | CE12: N/A | CG12: N/A | CH12: 5000 | CI12: O | CJ12: 2500 | CK12: O | CL12: 1500 | CM12: O | CN12: 1500 | CO12: O | CP12: 400 | CQ12: M | CR12: 300 | CS12: M | CT12: 125 | CU12: M | CW12: N/A | CY12: N/A | DA12: N/A | DB12: USD 100–750/hr (confirm with local office) | DC12: O | DD12: =ROUND(0.075*SUM(AD12,AF12,AH12,AJ12,AL12,AN12,AP12,AR12,AT12,AV12,AX12,AZ12,BB12,BR12,BT12,BV12,BX12,BZ12,CB12,CD12,CF12,CJ12,CL12,CN12,CP12,CR12,CT12,CV12,CX12,CZ12),0) -> 1374 | DE12: Bahamas#Fund#Bahamas ICON | DF12: =A12&"#"&C12&"#"&D12 -> Bahamas#Fund#Bahamas ICON | DG12: =DE12=DF12 -> TRUE
A13: ARGENTINA | DE13: ## | DF13: =A13&"#"&C13&"#"&D13 -> ARGENTINA##
A14: Argentina | B14: Carlos Fitte | C14: Trust | D14: Argentina Fideicomiso de Garantía | E14: USD | F14: Guarantee trust (fideicomiso) commonly used in Latin American jurisdictions. | G14: The Argentina Fideicomiso de Garantía is a trust structure regulated under local law and widely used by international clients of Amicorp. Guarantee trust (fideicomiso) commonly used in Latin American jurisdictions. Our local team manages incorporation, ongoing administration, accounting, and compliance so you can focus on commercial objectives instead of paperwork. | H14: 5-10 business days | I14: Annual trustee review, beneficiary statements, FATCA/CRS reporting where applicable | J14: Established Argentina legal framework familiar to investors, banks, and counterparties | K14: End-to-end Amicorp service: incorporation, registered office, directors, accounting, and reporting | L14: Treaty network and regulatory standing supporting cross-border investment and capital flows | M14: Single point of contact across 30+ jurisdictions for multi-entity group structures | N14: High-net-worth families consolidating assets across jurisdictions | O14: Succession and inheritance planning for global families | P14: Asset protection from political, creditor, or matrimonial risks | Q14: Holding shares of a private trust company or family business | R14: Asset protection from third-party claims | S14: Multi-generational succession planning | T14: Confidentiality and privacy of beneficial ownership | U14: Flexible distribution control by trustee | V14: Trust (Fideicomiso) | W14: Civil Law | X14: Assets segregated from fiduciario | Y14: CNV (Comisión Nacional de Valores) Civil and Commercial Code Art. 1666-1707 | Z14: No | AA14: 1 fiduciante + 1 fiduciario | AB14: Securing obligations in real estate or infrastructure financing transactions | AC14: Argentina FX controls and high inflation risk; complex tax treatment | AD14: 3500 | AE14: M | AG14: O | AI14: N/A | AK14: N/A | AL14: 0 | AM14: M | AO14: N/A | AP14: — | AQ14: N/A | AS14: M | AT14: — | AU14: O | AV14: — | AW14: M | AX14: — | AY14: M | AZ14: — | BA14: M | BC14: M | BD14: — | BE14: M | BF14: — | BG14: M | BI14: N/A | BK14: N/A | BM14: N/A | BO14: N/A | BQ14: N/A | BS14: N/A | BU14: N/A | BW14: N/A | BY14: N/A | CA14: N/A | CC14: N/A | CE14: N/A | CG14: N/A | CK14: N/A | CM14: N/A | CO14: N/A | CP14: 400 | CQ14: M | CS14: N/A | CU14: N/A | CW14: N/A | CY14: N/A | DA14: N/A | DB14: USD 100–750/hr (confirm with local office) | DC14: O | DD14: =ROUND(0.075*SUM(AD14,AF14,AH14,AJ14,AL14,AN14,AP14,AR14,AT14,AV14,AX14,AZ14,BB14,BR14,BT14,BV14,BX14,BZ14,CB14,CD14,CF14,CJ14,CL14,CN14,CP14,CR14,CT14,CV14,CX14,CZ14),0) -> 293 | DE14: Argentina#Trust#Argentina Fideicomiso de Garantía | DF14: =A14&"#"&C14&"#"&D14 -> Argentina#Trust#Argentina Fideicomiso de Garantía | DG14: =DE14=DF14 -> TRUE
A15: Argentina | B15: Carlos Fitte | C15: Trust | D15: Argentina Trust | E15: USD | F15: Discretionary or fixed trust structure for asset protection and succession planning. | G15: The Argentina Trust is a trust structure regulated under local law and widely used by international clients of Amicorp. Discretionary or fixed trust structure for asset protection and succession planning. Our local team manages incorporation, ongoing administration, accounting, and compliance so you can focus on commercial objectives instead of paperwork. | H15: 5-10 business days | I15: Annual trustee review, beneficiary statements, FATCA/CRS reporting where applicable | J15: Established Argentina legal framework familiar to investors, banks, and counterparties | K15: End-to-end Amicorp service: incorporation, registered office, directors, accounting, and reporting | L15: Treaty network and regulatory standing supporting cross-border investment and capital flows | M15: Single point of contact across 30+ jurisdictions for multi-entity group structures | N15: High-net-worth families consolidating assets across jurisdictions | O15: Succession and inheritance planning for global families | P15: Asset protection from political, creditor, or matrimonial risks | Q15: Holding shares of a private trust company or family business | R15: Asset protection from third-party claims | S15: Multi-generational succession planning | T15: Confidentiality and privacy of beneficial ownership | U15: Flexible distribution control by trustee | V15: Trust (Fideicomiso) | W15: Civil Law | X15: Assets segregated from fiduciario | Y15: BCRA / CNV Civil and Commercial Code Art. 1666-1707 | Z15: No | AA15: 1 fiduciante + 1 fiduciario | AB15: Succession planning and family asset management for Argentine resident families | AC15: Argentina capital controls; forced heirship rules may interact with trust terms | AD15: 5000 | AE15: M | AG15: O | AI15: N/A | AK15: N/A | AL15: 0 | AM15: M | AO15: N/A | AQ15: N/A | AR15: 4000 | AS15: M | AT15: — | AU15: O | AV15: — | AW15: M | AX15: — | AY15: M | AZ15: — | BA15: M | BC15: M | BD15: — | BE15: M | BF15: — | BG15: M | BI15: N/A | BK15: N/A | BM15: N/A | BO15: N/A | BQ15: N/A | BS15: N/A | BU15: N/A | BW15: N/A | BY15: N/A | CA15: N/A | CC15: N/A | CE15: N/A | CG15: N/A | CK15: N/A | CM15: N/A | CO15: N/A | CP15: 400 | CQ15: M | CS15: N/A | CU15: N/A | CW15: N/A | CY15: N/A | DA15: N/A | DB15: USD 100–750/hr (confirm with local office) | DC15: O | DD15: =ROUND(0.075*SUM(AD15,AF15,AH15,AJ15,AL15,AN15,AP15,AR15,AT15,AV15,AX15,AZ15,BB15,BR15,BT15,BV15,BX15,BZ15,CB15,CD15,CF15,CJ15,CL15,CN15,CP15,CR15,CT15,CV15,CX15,CZ15),0) -> 705 | DE15: Argentina#Trust#Argentina Trust | DF15: =A15&"#"&C15&"#"&D15 -> Argentina#Trust#Argentina Trust | DG15: =DE15=DF15 -> TRUE
A16: ABU DHABI | DE16: ## | DF16: =A16&"#"&C16&"#"&D16 -> ABU DHABI##
A17: Abu Dhabi | B17: Supriya Dixit Kambil | C17: Company | D17: Abu Dhabi ADGM SPV | E17: USD | F17: Abu Dhabi Global Market Special Purpose Vehicle for structured finance and investment holding. | G17: The Abu Dhabi ADGM SPV is an entity structure, regulated under English common law and widely used by local and international clients of Amicorp. Abu Dhabi Global Market Special Purpose Vehicle is used for isolating financial and legal risk by ring-fencing certain assets and liabilities for structured finance and investment holding. Our local team manages incorporation, ongoing administration, accounting, and compliance so you can focus on commercial objectives instead of paperwork. | H17: 10 business days | I17: Annual return filing , financial statements filing, and UBO declarations | J17: Established Abu Dhabi legal framework familiar to investors, banks, and counterparties | K17: End-to-end Amicorp service: incorporation, registered office, accounting, and reporting | L17: Treaty network and regulatory standing supporting cross-border investment and capital flows | M17: Single point of contact across 30+ jurisdictions for multi-entity group structures | N17: Holding investments into and out of Abu Dhabi | O17: Group holding companies and intermediate SPVs | P17: Joint ventures and shareholder agreements | Q17: Operating subsidiaries with local market access | R17: Limited liability for shareholders | S17: Separate legal entity | T17: Flexible management structure | U17: Tax efficient - 9% corporated tax is applicable | V17: Special Purpose Vehicle | W17: Common Law (English) | X17: Full | Y17: ADGM Registration Authority ADGM Companies Regulations 2020 | Z17: Yes (ADGM register) | AA17: 1 | AB17: Structured finance, securitisation, and cross-border M&A deal structuring | AC17: Must demonstrate nexus to ADGM; annual substance fees apply | AD17: 5000 | AE17: M | AF17: NA | AG17: O | AH17: 500 | AI17: M | AK17: O | AL17: 0 | AM17: O | AN17: 2000 | AO17: O | AP17: — | AQ17: O | AR17: NA | AS17: N/A | AT17: — | AU17: O | AV17: 1600 | AW17: M | AX17: — | AY17: O | AZ17: 1900 | BA17: M | BC17: O | BD17: 1500 | BE17: O | BF17: — | BG17: N/A | BH17: NA | BI17: N/A | BJ17: NA | BK17: N/A | BL17: 1600 | BM17: O | BN17: NA | BO17: N/A | BP17: Mandatory | BQ17: O | BS17: N/A | BU17: N/A | BW17: N/A | BY17: N/A | CA17: N/A | CC17: N/A | CE17: N/A | CG17: N/A | CK17: N/A | CM17: N/A | CO17: N/A | CP17: 400 | CQ17: M | CS17: N/A | CU17: N/A | CW17: N/A | CY17: N/A | DA17: N/A | DB17: USD 100–750/hr (confirm with local office) | DC17: O | DD17: =ROUND(0.075*SUM(AD17,AF17,AH17,AJ17,AL17,AN17,AP17,AR17,AT17,AV17,AX17,AZ17,BB17,BR17,BT17,BV17,BX17,BZ17,CB17,CD17,CF17,CJ17,CL17,CN17,CP17,CR17,CT17,CV17,CX17,CZ17),0) -> 855 | DE17: Abu Dhabi#Company#Abu Dhabi ADGM SPV | DF17: =A17&"#"&C17&"#"&D17 -> Abu Dhabi#Company#Abu Dhabi ADGM SPV | DG17: =DE17=DF17 -> TRUE
A18: Abu Dhabi | B18: Supriya Dixit Kambil | C18: Company | D18: Abu Dhabi ADGM - Private Limited Company | E18: USD | F18: Private company limited by shares established in the Abu Dhabi Global Market financial free zone. | G18: The Abu Dhabi ADGM - Private Private company limited by shares is a entity structure regulated under English Common law and widely used by local and international clients of Amicorp. Our local team manages incorporation, ongoing administration, accounting, and compliance so you can focus on commercial objectives instead of paperwork. | H18: 10 business days | I18: Annual return, financial statements filing, and economic substance / UBO declarations | J18: Established Abu Dhabi legal framework familiar to investors, banks, and counterparties | K18: End-to-end Amicorp service: incorporation, coordination for lease agreement, accounting, and reporting | L18: Treaty network and regulatory standing supporting cross-border investment and capital flows | M18: Single point of contact across 30+ jurisdictions for multi-entity group structures | N18: Holding investments into and out of Abu Dhabi, providing operational services in ADGM free zone and outside UAE only. | P18: Joint ventures and shareholder agreements | Q18: Operating subsidiaries with access to ADGM free zone and outside UAE market | R18: Limited liability for shareholders | S18: Separate legal entity | T18: Flexible management structure | U18: Tax efficient - 9% corporated tax is applicable | V18: Limited Company | W18: Common Law (English) | X18: Full | Y18: ADGM Registration Authority ADGM Companies Regulations 2020 | Z18: Yes (ADGM register) | AA18: 1 | AB18: Holding company and operating company providing services in ADGM and outside UAE | AC18: Must maintain ADGM office presence and hire minimum 1 employee to fulfil ADGM economic substance requirements; 9% UAE CT and 0% UAE CT for qualifying income only | AD18: 6000 | AE18: M | AG18: O | AH18: 500 | AI18: M | AK18: O | AL18: 0 | AM18: O | AN18: 2000 | AO18: O | AP18: — | AQ18: O | AR18: NA | AS18: N/A | AT18: — | AU18: O | AV18: lease agreement is required from the client at the time of oncorporation | AW18: M | AX18: — | AY18: O | AZ18: 5800 | BA18: M | BC18: O | BD18: 1500 | BE18: O | BF18: — | BG18: N/A | BH18: NA | BI18: N/A | BJ18: Mandatory - from ADGM registered auditors | BK18: O | BL18: 1600 | BM18: O | BN18: NA | BO18: N/A | BP18: Mandatory | BQ18: O | BS18: N/A | BU18: N/A | BW18: N/A | BY18: N/A | CA18: N/A | CC18: N/A | CE18: N/A | CG18: N/A | CK18: N/A | CM18: N/A | CO18: N/A | CP18: 400 | CQ18: M | CS18: N/A | CU18: N/A | CW18: N/A | CY18: N/A | DA18: N/A | DB18: USD 100–750/hr (confirm with local office) | DC18: O | DD18: =ROUND(0.075*SUM(AD18,AF18,AH18,AJ18,AL18,AN18,AP18,AR18,AT18,AV18,AX18,AZ18,BB18,BR18,BT18,BV18,BX18,BZ18,CB18,CD18,CF18,CJ18,CL18,CN18,CP18,CR18,CT18,CV18,CX18,CZ18),0) -> 1103 | DE18: Abu Dhabi#Company#Abu Dhabi ADGM - Private Limited Company | DF18: =A18&"#"&C18&"#"&D18 -> Abu Dhabi#Company#Abu Dhabi ADGM - Private Limited Company | DG18: =DE18=DF18 -> TRUE
A19: Abu Dhabi | B19: Supriya Dixit Kambil | C19: Company | D19: Abu Dhabi ADGM - Foundation | E19: USD | F19: Foundation structure suitable for wealth management and succession plannng. A common choice among HNWI | G19: The Abu Dhabi Foundation is regulated under english common local law and widely used by local and international clients of Amicorp. Our local team manages incorporation, ongoing administration, accounting, and compliance so you can focus on commercial objectives instead of paperwork. | H19: 10 business days | I19: Annual return, financial statements filing, and economic substance / UBO declarations | J19: Established Abu Dhabi legal framework familiar to investors, banks, and counterparties | K19: End-to-end Amicorp service: incorporation, registered office, accounting, and reporting | L19: Treaty network and regulatory standing supporting cross-border investment and capital flows | M19: Single point of contact across 30+ jurisdictions for multi-entity group structures | N19: Wealth management and succession planning, | O19: Succession and inheritance planning for global families | P19: High-net-worth families consolidating assets across jurisdictions | S19: Separate legal entity | T19: Flexible management structure | U19: Tax efficient - 9% corporated tax is applicable | V19: Other - Foundation | W19: Common Law (English) | X19: Varies by structure as defined in the charter of the foundation | Y19: ADGM Registration Authority ADGM Foundation Regulations 2017 | Z19: Yes | AA19: Varies Founder, minimum 2 council members, beneficiaries | AC19: Foundation is eligible to 9% UAE CT and 0% UAE CT if qualified as exempt by FTA | AD19: 5500 | AE19: M | AF19: NA | AG19: O | AH19: 500 | AI19: M | AK19: O | AL19: 0 | AM19: O | AN19: 2000 | AO19: O | AP19: 15000 | AQ19: O | AR19: NA | AS19: N/A | AT19: — | AU19: O | AV19: 1600 | AW19: M | AX19: — | AY19: O | AZ19: 1000 | BA19: M | BC19: O | BD19: 1500 | BE19: O | BF19: — | BG19: N/A | BH19: NA | BI19: N/A | BJ19: NA | BK19: N/A | BL19: 1600 | BM19: O | BN19: NA | BO19: N/A | BP19: Yes | BQ19: O | BS19: N/A | BU19: N/A | BW19: N/A | BY19: N/A | CA19: N/A | CC19: N/A | CE19: N/A | CG19: N/A | CK19: N/A | CM19: N/A | CO19: N/A | CP19: 400 | CQ19: M | CS19: N/A | CU19: N/A | CW19: N/A | CY19: N/A | DA19: N/A | DB19: USD 100–750/hr (confirm with local office) | DC19: O | DD19: =ROUND(0.075*SUM(AD19,AF19,AH19,AJ19,AL19,AN19,AP19,AR19,AT19,AV19,AX19,AZ19,BB19,BR19,BT19,BV19,BX19,BZ19,CB19,CD19,CF19,CJ19,CL19,CN19,CP19,CR19,CT19,CV19,CX19,CZ19),0) -> 1950 | DE19: Abu Dhabi#Company#Abu Dhabi ADGM - Foundation | DF19: =A19&"#"&C19&"#"&D19 -> Abu Dhabi#Company#Abu Dhabi ADGM - Foundation | DG19: =DE19=DF19 -> TRUE
A20: BRAZIL | DE20: ## | DF20: =A20&"#"&C20&"#"&D20 -> BRAZIL##
A21: Brazil | B21: Marco Navarro | C21: Fund | D21: Brazil FI | E21: USD | F21: Brazilian Fundo de Investimento — standard investment fund vehicle. | G21: The Brazil FI is a fund structure regulated under local law and widely used by international clients of Amicorp. Brazilian Fundo de Investimento — standard investment fund vehicle. Our local team manages incorporation, ongoing administration, accounting, and compliance so you can focus on commercial objectives instead of paperwork. | H21: 4-6 weeks | I21: Annual audited financials, regulator filings, AML/KYC monitoring, and investor reporting | J21: Established Brazil legal framework familiar to investors, banks, and counterparties | K21: End-to-end Amicorp service: incorporation, registered office, directors, accounting, and reporting | L21: Treaty network and regulatory standing supporting cross-border investment and capital flows | M21: Single point of contact across 30+ jurisdictions for multi-entity group structures | N21: Asset managers launching regulated or private funds | O21: PE/VC sponsors raising committed capital from institutional LPs | P21: Family offices pooling investments across asset classes | Q21: Structured products and securitisation arrangers | R21: Pooled capital with professional management | S21: Investor-friendly structure with familiar legal precedent | T21: Tax-efficient flow-through or treaty-eligible vehicle | U21: Scalable for additional sub-funds or share classes | V21: Investment Fund (Regulated) | W21: Civil Law | X21: Full (condominium structure, not entity) | Y21: CVM (Comissão de Valores Mobiliários) CVM Resolution 175/2022; Law 8,668/93 | Z21: Yes (CVM registration) | AA21: 1 administrator + 1 investor | AB21: Brazilian domestic investment fund for diversified fixed income or multi-asset portfolios | AC21: Brazilian FX controls; mandatory local administrator; CVM reporting requirements | AE21: M | AG21: O | AI21: N/A | AK21: N/A | AL21: 0 | AM21: M | AO21: N/A | AP21: — | AQ21: M | AS21: N/A | AT21: — | AU21: O | AV21: — | AW21: M | AX21: — | AY21: M | AZ21: — | BA21: M | BC21: M | BD21: — | BE21: M | BF21: — | BG21: M | BI21: N/A | BK21: N/A | BM21: N/A | BO21: N/A | BQ21: N/A | BR21: 15000 | BS21: M | BU21: N/A | BW21: N/A | BY21: N/A | CA21: N/A | CB21: 2-8 Basispoints (2,000 USD per month minimum fee) | CC21: O | CE21: N/A | CG21: N/A | CI21: O | CJ21: 2500 | CK21: O | CL21: 1500 | CM21: O | CN21: 1500 | CO21: O | CP21: 400 | CQ21: M | CS21: N/A | CU21: N/A | CW21: N/A | CY21: N/A | DA21: N/A | DB21: USD 100–750/hr (confirm with local office) | DC21: O | DD21: =ROUND(0.075*SUM(AD21,AF21,AH21,AJ21,AL21,AN21,AP21,AR21,AT21,AV21,AX21,AZ21,BB21,BR21,BT21,BV21,BX21,BZ21,CB21,CD21,CF21,CJ21,CL21,CN21,CP21,CR21,CT21,CV21,CX21,CZ21),0) -> 1568 | DE21: Brazil#Fund#Brazil FI | DF21: =A21&"#"&C21&"#"&D21 -> Brazil#Fund#Brazil FI | DG21: =DE21=DF21 -> TRUE
A22: Brazil | B22: Marco Navarro | C22: Fund | D22: Brazil FIC | E22: USD | F22: Brazilian Fundo de Investimento em Cotas — fund of funds structure. | G22: The Brazil FIC is a fund structure regulated under local law and widely used by international clients of Amicorp. Brazilian Fundo de Investimento em Cotas — fund of funds structure. Our local team manages incorporation, ongoing administration, accounting, and compliance so you can focus on commercial objectives instead of paperwork. | H22: 4-6 weeks | I22: Annual audited financials, regulator filings, AML/KYC monitoring, and investor reporting | J22: Established Brazil legal framework familiar to investors, banks, and counterparties | K22: End-to-end Amicorp service: incorporation, registered office, directors, accounting, and reporting | L22: Treaty network and regulatory standing supporting cross-border investment and capital flows | M22: Single point of contact across 30+ jurisdictions for multi-entity group structures | N22: Asset managers launching regulated or private funds | O22: PE/VC sponsors raising committed capital from institutional LPs | P22: Family offices pooling investments across asset classes | Q22: Structured products and securitisation arrangers | R22: Pooled capital with professional management | S22: Investor-friendly structure with familiar legal precedent | T22: Tax-efficient flow-through or treaty-eligible vehicle | U22: Scalable for additional sub-funds or share classes | V22: Investment Fund (Regulated) | W22: Civil Law | X22: Full | Y22: CVM CVM Resolution 175/2022 | Z22: Yes | AA22: 1+ | AB22: Fund-of-funds structure for institutional investors allocating to multiple Brazilian funds | AC22: Double fee layer (FIC + underlying FI); concentration limits apply | AE22: M | AG22: O | AI22: N/A | AK22: N/A | AL22: 0 | AM22: M | AO22: N/A | AP22: — | AQ22: M | AS22: N/A | AT22: — | AU22: O | AV22: — | AW22: M | AX22: — | AY22: M | AZ22: — | BA22: M | BC22: M | BD22: — | BE22: M | BF22: — | BG22: M | BI22: N/A | BK22: N/A | BM22: N/A | BO22: N/A | BQ22: N/A | BR22: 15000 | BS22: M | BU22: N/A | BW22: N/A | BY22: N/A | CA22: N/A | CB22: 2-8 Basispoints (2,000 USD per month minimum fee) | CC22: O | CE22: N/A | CG22: N/A | CI22: O | CJ22: 2500 | CK22: O | CL22: 1500 | CM22: O | CN22: 1500 | CO22: O | CP22: 400 | CQ22: M | CS22: N/A | CU22: N/A | CW22: N/A | CY22: N/A | DA22: N/A | DB22: USD 100–750/hr (confirm with local office) | DC22: O | DD22: =ROUND(0.075*SUM(AD22,AF22,AH22,AJ22,AL22,AN22,AP22,AR22,AT22,AV22,AX22,AZ22,BB22,BR22,BT22,BV22,BX22,BZ22,CB22,CD22,CF22,CJ22,CL22,CN22,CP22,CR22,CT22,CV22,CX22,CZ22),0) -> 1568 | DE22: Brazil#Fund#Brazil FIC | DF22: =A22&"#"&C22&"#"&D22 -> Brazil#Fund#Brazil FIC | DG22: =DE22=DF22 -> TRUE
A23: Brazil | B23: Marco Navarro | C23: Fund | D23: Brazil FIA | E23: USD | F23: Brazilian Fundo de Investimento em Ações — equity investment fund. | G23: The Brazil FIA is a fund structure regulated under local law and widely used by international clients of Amicorp. Brazilian Fundo de Investimento em Ações — equity investment fund. Our local team manages incorporation, ongoing administration, accounting, and compliance so you can focus on commercial objectives instead of paperwork. | H23: 4-6 weeks | I23: Annual audited financials, regulator filings, AML/KYC monitoring, and investor reporting | J23: Established Brazil legal framework familiar to investors, banks, and counterparties | K23: End-to-end Amicorp service: incorporation, registered office, directors, accounting, and reporting | L23: Treaty network and regulatory standing supporting cross-border investment and capital flows | M23: Single point of contact across 30+ jurisdictions for multi-entity group structures | N23: Asset managers launching regulated or private funds | O23: PE/VC sponsors raising committed capital from institutional LPs | P23: Family offices pooling investments across asset classes | Q23: Structured products and securitisation arrangers | R23: Pooled capital with professional management | S23: Investor-friendly structure with familiar legal precedent | T23: Tax-efficient flow-through or treaty-eligible vehicle | U23: Scalable for additional sub-funds or share classes | V23: Investment Fund (Regulated) | W23: Civil Law | X23: Full | Y23: CVM CVM Resolution 175/2022 | Z23: Yes | AA23: 1+ | AB23: Brazilian equity investment fund investing ≥67% in listed equities (Bovespa) | AC23: FX risk; high volatility in Brazilian equity markets; BRL hedging cost | AE23: M | AG23: O | AI23: N/A | AK23: N/A | AL23: 0 | AM23: M | AO23: N/A | AP23: — | AQ23: M | AS23: N/A | AT23: — | AU23: O | AV23: — | AW23: M | AX23: — | AY23: M | AZ23: — | BA23: M | BC23: M | BD23: — | BE23: M | BF23: — | BG23: M | BI23: N/A | BK23: N/A | BM23: N/A | BO23: N/A | BQ23: N/A | BR23: 15000 | BS23: M | BU23: N/A | BW23: N/A | BY23: N/A | CA23: N/A | CB23: 2-8 Basispoints (2,000 USD per month minimum fee) | CC23: O | CE23: N/A | CG23: N/A | CI23: O | CJ23: 2500 | CK23: O | CL23: 1500 | CM23: O | CN23: 1500 | CO23: O | CP23: 400 | CQ23: M | CS23: N/A | CU23: N/A | CW23: N/A | CY23: N/A | DA23: N/A | DB23: USD 100–750/hr (confirm with local office) | DC23: O | DD23: =ROUND(0.075*SUM(AD23,AF23,AH23,AJ23,AL23,AN23,AP23,AR23,AT23,AV23,AX23,AZ23,BB23,BR23,BT23,BV23,BX23,BZ23,CB23,CD23,CF23,CJ23,CL23,CN23,CP23,CR23,CT23,CV23,CX23,CZ23),0) -> 1568 | DE23: Brazil#Fund#Brazil FIA | DF23: =A23&"#"&C23&"#"&D23 -> Brazil#Fund#Brazil FIA | DG23: =DE23=DF23 -> TRUE
A24: Brazil | B24: Marco Navarro | C24: Fund | D24: Brazil FIP | E24: USD | F24: Brazilian Fundo de Investimento em Participações — private equity fund. | G24: The Brazil FIP is a fund structure regulated under local law and widely used by international clients of Amicorp. Brazilian Fundo de Investimento em Participações — private equity fund. Our local team manages incorporation, ongoing administration, accounting, and compliance so you can focus on commercial objectives instead of paperwork. | H24: 4-6 weeks | I24: Annual audited financials, regulator filings, AML/KYC monitoring, and investor reporting | J24: Established Brazil legal framework familiar to investors, banks, and counterparties | K24: End-to-end Amicorp service: incorporation, registered office, directors, accounting, and reporting | L24: Treaty network and regulatory standing supporting cross-border investment and capital flows | M24: Single point of contact across 30+ jurisdictions for multi-entity group structures | N24: Asset managers launching regulated or private funds | O24: PE/VC sponsors raising committed capital from institutional LPs | P24: Family offices pooling investments across asset classes | Q24: Structured products and securitisation arrangers | R24: Pooled capital with professional management | S24: Investor-friendly structure with familiar legal precedent | T24: Tax-efficient flow-through or treaty-eligible vehicle | U24: Scalable for additional sub-funds or share classes | V24: Investment Fund (AIF) | W24: Civil Law | X24: Full | Y24: CVM CVM Resolution 175/2022; Law 12,431/11 | Z24: Yes | AA24: 1+ | AB24: Private equity and buyout fund investing in Brazilian non-listed companies | AC24: Minimum 10-year term; governance and reporting requirements under CVM | AE24: M | AG24: O | AI24: N/A | AK24: N/A | AL24: 0 | AM24: M | AO24: N/A | AP24: — | AQ24: M | AS24: N/A | AT24: — | AU24: O | AV24: — | AW24: M | AX24: — | AY24: M | AZ24: — | BA24: M | BC24: M | BD24: — | BE24: M | BF24: — | BG24: M | BI24: N/A | BK24: N/A | BM24: N/A | BO24: N/A | BQ24: N/A | BR24: 15000 | BS24: M | BU24: N/A | BW24: N/A | BY24: N/A | CA24: N/A | CB24: 2-8 Basispoints (2,000 USD per month minimum fee) | CC24: O | CE24: N/A | CG24: N/A | CI24: O | CJ24: 2500 | CK24: O | CL24: 1500 | CM24: O | CN24: 1500 | CO24: O | CP24: 400 | CQ24: M | CS24: N/A | CU24: N/A | CW24: N/A | CY24: N/A | DA24: N/A | DB24: USD 100–750/hr (confirm with local office) | DC24: O | DD24: =ROUND(0.075*SUM(AD24,AF24,AH24,AJ24,AL24,AN24,AP24,AR24,AT24,AV24,AX24,AZ24,BB24,BR24,BT24,BV24,BX24,BZ24,CB24,CD24,CF24,CJ24,CL24,CN24,CP24,CR24,CT24,CV24,CX24,CZ24),0) -> 1568 | DE24: Brazil#Fund#Brazil FIP | DF24: =A24&"#"&C24&"#"&D24 -> Brazil#Fund#Brazil FIP | DG24: =DE24=DF24 -> TRUE
A25: Brazil | B25: Marco Navarro | C25: Fund | D25: Brazil FII | E25: USD | F25: Brazilian Fundo de Investimento Imobiliário — real estate investment fund. | G25: The Brazil FII is a fund structure regulated under local law and widely used by international clients of Amicorp. Brazilian Fundo de Investimento Imobiliário — real estate investment fund. Our local team manages incorporation, ongoing administration, accounting, and compliance so you can focus on commercial objectives instead of paperwork. | H25: 4-6 weeks | I25: Annual audited financials, regulator filings, AML/KYC monitoring, and investor reporting | J25: Established Brazil legal framework familiar to investors, banks, and counterparties | K25: End-to-end Amicorp service: incorporation, registered office, directors, accounting, and reporting | L25: Treaty network and regulatory standing supporting cross-border investment and capital flows | M25: Single point of contact across 30+ jurisdictions for multi-entity group structures | N25: Asset managers launching regulated or private funds | O25: PE/VC sponsors raising committed capital from institutional LPs | P25: Family offices pooling investments across asset classes | Q25: Structured products and securitisation arrangers | R25: Pooled capital with professional management | S25: Investor-friendly structure with familiar legal precedent | T25: Tax-efficient flow-through or treaty-eligible vehicle | U25: Scalable for additional sub-funds or share classes | V25: REIT/Business Trust | W25: Civil Law | X25: Full | Y25: CVM Law 8,668/93; CVM Resolution 175/2022 | Z25: Yes | AA25: 1+ | AB25: Real estate investment trust listed on B3 for retail and institutional investors | AC25: Must distribute ≥95% of income semi-annually; minimum 50 investors for tax exemption | AE25: M | AG25: O | AI25: N/A | AK25: N/A | AL25: 0 | AM25: M | AO25: N/A | AP25: — | AQ25: M | AS25: N/A | AT25: — | AU25: O | AV25: — | AW25: M | AX25: — | AY25: M | AZ25: — | BA25: M | BC25: M | BD25: — | BE25: M | BF25: — | BG25: M | BI25: N/A | BK25: N/A | BM25: N/A | BO25: N/A | BQ25: N/A | BR25: 15000 | BS25: M | BU25: N/A | BW25: N/A | BY25: N/A | CA25: N/A | CB25: 2-8 Basispoints (2,000 USD per month minimum fee) | CC25: O | CE25: N/A | CG25: N/A | CI25: O | CJ25: 2500 | CK25: O | CL25: 1500 | CM25: O | CN25: 1500 | CO25: O | CP25: 400 | CQ25: M | CS25: N/A | CU25: N/A | CW25: N/A | CY25: N/A | DA25: N/A | DB25: USD 100–750/hr (confirm with local office) | DC25: O | DD25: =ROUND(0.075*SUM(AD25,AF25,AH25,AJ25,AL25,AN25,AP25,AR25,AT25,AV25,AX25,AZ25,BB25,BR25,BT25,BV25,BX25,BZ25,CB25,CD25,CF25,CJ25,CL25,CN25,CP25,CR25,CT25,CV25,CX25,CZ25),0) -> 1568 | DE25: Brazil#Fund#Brazil FII | DF25: =A25&"#"&C25&"#"&D25 -> Brazil#Fund#Brazil FII | DG25: =DE25=DF25 -> TRUE
A26: Brazil | B26: Marco Navarro | C26: Fund | D26: Brazil FI-Infra | E26: USD | F26: Brazilian infrastructure investment fund for long-term infrastructure projects. | G26: The Brazil FI-Infra is a fund structure regulated under local law and widely used by international clients of Amicorp. Brazilian infrastructure investment fund for long-term infrastructure projects. Our local team manages incorporation, ongoing administration, accounting, and compliance so you can focus on commercial objectives instead of paperwork. | H26: 4-6 weeks | I26: Annual audited financials, regulator filings, AML/KYC monitoring, and investor reporting | J26: Established Brazil legal framework familiar to investors, banks, and counterparties | K26: End-to-end Amicorp service: incorporation, registered office, directors, accounting, and reporting | L26: Treaty network and regulatory standing supporting cross-border investment and capital flows | M26: Single point of contact across 30+ jurisdictions for multi-entity group structures | N26: Asset managers launching regulated or private funds | O26: PE/VC sponsors raising committed capital from institutional LPs | P26: Family offices pooling investments across asset classes | Q26: Structured products and securitisation arrangers | R26: Pooled capital with professional management | S26: Investor-friendly structure with familiar legal precedent | T26: Tax-efficient flow-through or treaty-eligible vehicle | U26: Scalable for additional sub-funds or share classes | V26: Investment Fund (AIF) | W26: Civil Law | X26: Full | Y26: CVM Law 12,431/2011; CVM Resolution 175/2022 | Z26: Yes | AA26: 1+ | AB26: Infrastructure debt fund investing in regulated infrastructure assets (energy, sanitation, transport) | AC26: Must invest ≥85% in infrastructure debentures; long lock-up periods typical | AE26: M | AG26: O | AI26: N/A | AK26: N/A | AL26: 0 | AM26: M | AO26: N/A | AP26: — | AQ26: M | AS26: N/A | AT26: — | AU26: O | AV26: — | AW26: M | AX26: — | AY26: M | AZ26: — | BA26: M | BC26: M | BD26: — | BE26: M | BF26: — | BG26: M | BI26: N/A | BK26: N/A | BM26: N/A | BO26: N/A | BQ26: N/A | BR26: 15000 | BS26: M | BU26: N/A | BW26: N/A | BY26: N/A | CA26: N/A | CB26: 2-8 Basispoints (2,000 USD per month minimum fee) | CC26: O | CE26: N/A | CG26: N/A | CI26: O | CJ26: 2500 | CK26: O | CL26: 1500 | CM26: O | CN26: 1500 | CO26: O | CP26: 400 | CQ26: M | CS26: N/A | CU26: N/A | CW26: N/A | CY26: N/A | DA26: N/A | DB26: USD 100–750/hr (confirm with local office) | DC26: O | DD26: =ROUND(0.075*SUM(AD26,AF26,AH26,AJ26,AL26,AN26,AP26,AR26,AT26,AV26,AX26,AZ26,BB26,BR26,BT26,BV26,BX26,BZ26,CB26,CD26,CF26,CJ26,CL26,CN26,CP26,CR26,CT26,CV26,CX26,CZ26),0) -> 1568 | DE26: Brazil#Fund#Brazil FI-Infra | DF26: =A26&"#"&C26&"#"&D26 -> Brazil#Fund#Brazil FI-Infra | DG26: =DE26=DF26 -> TRUE
A27: BRITISH VIRGIN ISLANDS | DE27: ## | DF27: =A27&"#"&C27&"#"&D27 -> BRITISH VIRGIN ISLANDS##
A28: British Virgin Islands | B28: Pedro Garcia | C28: Company | D28: British Virgin Islands BVIBC | E28: USD | F28: BVI Business Company, a flexible tax-neutral vehicle widely used for international holding and trading activities. | G28: The British Virgin Islands BVIBC is a entity structure regulated under local law and widely used by international clients of Amicorp. BVI Business Company, a flexible tax-neutral vehicle widely used for international holding and trading activities. Our local team manages incorporation, ongoing administration, accounting, and compliance so you can focus on commercial objectives instead of paperwork. | H28: 3-7 business days | I28: Annual return, financial statements filing, and economic substance / UBO declarations | J28: Established British Virgin Islands legal framework familiar to investors, banks, and counterparties | K28: End-to-end Amicorp service: incorporation, registered office, directors, accounting, and reporting | L28: Treaty network and regulatory standing supporting cross-border investment and capital flows | M28: Single point of contact across 30+ jurisdictions for multi-entity group structures | N28: Holding investments into and out of British Virgin Islands | O28: Group holding companies and intermediate SPVs | P28: Joint ventures and shareholder agreements | Q28: Operating subsidiaries with local market access | R28: Limited liability for shareholders | S28: Separate legal entity | T28: Flexible management structure | U28: Tax efficient | V28: IBC | W28: Common Law | X28: Full | Y28: BVI Financial Services Commission BVI Business Companies Act 2004 (as amended) | Z28: No (beneficial ownership in private register) | AA28: 1 | AB28: Holding structure for international investments, IP, or cross-border M&A SPVs | AC28: Economic substance rules for holding companies; FATF/OECD grey-list risk for certain activities | AD28: 1780 | AE28: M | AG28: O | AI28: N/A | AK28: N/A | AL28: 0 | AM28: M | AO28: N/A | AP28: 2500 | AQ28: O | AS28: N/A | AT28: — | AU28: O | AV28: 930 | AW28: M | AX28: 1010 | AY28: 0 | AZ28: 550 | BA28: M | BC28: M | BD28: 1000 | BE28: O | BF28: 1500 | BG28: O | BI28: N/A | BK28: N/A | BL28: 350 | BM28: O | BN28: 125 | BO28: O | BQ28: N/A | BS28: N/A | BU28: N/A | BW28: N/A | BY28: N/A | CA28: N/A | CC28: N/A | CE28: N/A | CG28: N/A | CK28: N/A | CM28: N/A | CO28: N/A | CP28: 400 | CQ28: M | CR28: 300 | CS28: M | CT28: 125 | CU28: M | CW28: N/A | CY28: N/A | DA28: N/A | DB28: USD 100–750/hr (confirm with local office) | DC28: O | DD28: =ROUND(0.075*SUM(AD28,AF28,AH28,AJ28,AL28,AN28,AP28,AR28,AT28,AV28,AX28,AZ28,BB28,BR28,BT28,BV28,BX28,BZ28,CB28,CD28,CF28,CJ28,CL28,CN28,CP28,CR28,CT28,CV28,CX28,CZ28),0) -> 570 | DE28: British Virgin Islands#Company#British Virgin Islands BVIBC | DF28: =A28&"#"&C28&"#"&D28 -> British Virgin Islands#Company#British Virgin Islands BVIBC | DG28: =DE28=DF28 -> TRUE
A29: British Virgin Islands | B29: Pedro Garcia | C29: Company | D29: British Virgin Islands SPC | E29: USD | F29: Segregated Portfolio Company allowing creation of ring-fenced portfolios within a single legal entity. | G29: The British Virgin Islands SPC is a entity structure regulated under local law and widely used by international clients of Amicorp. Segregated Portfolio Company allowing creation of ring-fenced portfolios within a single legal entity. Our local team manages incorporation, ongoing administration, accounting, and compliance so you can focus on commercial objectives instead of paperwork. | H29: 3-7 business days | I29: Annual return, financial statements filing, and economic substance / UBO declarations | J29: Established British Virgin Islands legal framework familiar to investors, banks, and counterparties | K29: End-to-end Amicorp service: incorporation, registered office, directors, accounting, and reporting | L29: Treaty network and regulatory standing supporting cross-border investment and capital flows | M29: Single point of contact across 30+ jurisdictions for multi-entity group structures | N29: Holding investments into and out of British Virgin Islands | O29: Group holding companies and intermediate SPVs | P29: Joint ventures and shareholder agreements | Q29: Operating subsidiaries with local market access | R29: Limited liability for shareholders | S29: Separate legal entity | T29: Flexible management structure | U29: Tax efficient | V29: Segregated Portfolio Company | W29: Common Law | X29: Full (statutory cell segregation) | Y29: BVI Financial Services Commission BVI Business Companies Act 2004 (SPC provisions) | Z29: No | AA29: 1 | AB29: Multi-class hedge fund or insurance vehicle with legally ring-fenced portfolios | AC29: Requires FSC approval; cell segregation may not be recognised in non-BVI courts | AD29: 3500 | AE29: M | AG29: O | AI29: N/A | AK29: N/A | AL29: 0 | AM29: M | AO29: N/A | AP29: 2800 | AQ29: M | AS29: N/A | AT29: — | AU29: O | AV29: 930 | AW29: M | AX29: — | AY29: 0 | AZ29: — | BA29: M | BC29: M | BD29: — | BE29: M | BF29: — | BG29: M | BI29: N/A | BK29: N/A | BM29: N/A | BO29: N/A | BQ29: N/A | BS29: N/A | BU29: N/A | BW29: N/A | BY29: N/A | CA29: N/A | CC29: N/A | CE29: N/A | CG29: N/A | CK29: N/A | CM29: N/A | CO29: N/A | CP29: 400 | CQ29: M | CR29: 300 | CS29: M | CT29: 125 | CU29: M | CW29: N/A | CY29: N/A | DA29: N/A | DB29: USD 100–750/hr (confirm with local office) | DC29: O | DD29: =ROUND(0.075*SUM(AD29,AF29,AH29,AJ29,AL29,AN29,AP29,AR29,AT29,AV29,AX29,AZ29,BB29,BR29,BT29,BV29,BX29,BZ29,CB29,CD29,CF29,CJ29,CL29,CN29,CP29,CR29,CT29,CV29,CX29,CZ29),0) -> 604 | DE29: British Virgin Islands#Company#British Virgin Islands SPC | DF29: =A29&"#"&C29&"#"&D29 -> British Virgin Islands#Company#British Virgin Islands SPC | DG29: =DE29=DF29 -> TRUE
